Workbook

Sheet Savings Percent
A1: Savings Percent
A2: Shower | B2: Toilet | C2: Faucet | D2: Laundry | E2: Dishwasher | F2: Outdoor | H2: Bins | I2: Shower | J2: Toilet | K2: Faucet | L2: Laundry | M2: Dishwasher | N2: Outdoor
A3: =MCWaterSavings!B2/MCWaterBefore!B2 -> 0.4 | B3: =MCWaterSavings!C2/MCWaterBefore!C2 -> 0 | C3: =MCWaterSavings!D2/MCWaterBefore!D2 -> 0.59090909 | D3: =MCWaterSavings!E2/MCWaterBefore!E2 -> 0 | E3: =MCWaterSavings!F2/MCWaterBefore!F2 -> 0 | F3: =MCWaterSavings!G2/MCWaterBefore!G2 -> 0.33208927 | H3: 0 | I3: =COUNTIF(A3:A252,0) -> 32 | J3: =COUNTIF(B3:B252,0) -> 69 | K3: =COUNTIF(C3:C252,0) -> 37 | L3: =COUNTIF(D3:D252,0) -> 112 | M3: =COUNTIF(E3:E252,0) -> 100 | N3: =COUNTIF(F3:F252,0) -> 124
A4: =MCWaterSavings!B3/MCWaterBefore!B3 -> 0.28571429 | B4: =MCWaterSavings!C3/MCWaterBefore!C3 -> 0.38461538 | C4: =MCWaterSavings!D3/MCWaterBefore!D3 -> 0 | D4: =MCWaterSavings!E3/MCWaterBefore!E3 -> 0 | E4: =MCWaterSavings!F3/MCWaterBefore!F3 -> 0 | F4: =MCWaterSavings!G3/MCWaterBefore!G3 -> 0 | H4: 1% - 10% | I4: =COUNTIF(A3:A252,"<=0.1")-I3 -> 10 | J4: =COUNTIF(B3:B252,"<=0.1")-J3 -> 48 | K4: =COUNTIF(C3:C252,"<=0.1")-K3 -> 18 | L4: =COUNTIF(D3:D252,"<=0.1")-L3 -> 0 | M4: =COUNTIF(E3:E252,"<=0.1")-M3 -> 29 | N4: =COUNTIF(F3:F252,"<=0.1")-N3 -> 3
A5: =MCWaterSavings!B4/MCWaterBefore!B4 -> 0.4 | B5: =MCWaterSavings!C4/MCWaterBefore!C4 -> 1.4544934e-16 | C5: =MCWaterSavings!D4/MCWaterBefore!D4 -> 0 | D5: =MCWaterSavings!E4/MCWaterBefore!E4 -> 0 | E5: =MCWaterSavings!F4/MCWaterBefore!F4 -> 0 | F5: =MCWaterSavings!G4/MCWaterBefore!G4 -> 0.34731187 | H5: 11% - 20% | I5: =COUNTIF(A3:A253,"<=0.2")-I4-I3 -> 6 | J5: =COUNTIF(B3:B253,"<=0.2")-J4-J3 -> 0 | K5: =COUNTIF(C3:C253,"<=0.2")-K4-K3 -> 0 | L5: =COUNTIF(D3:D253,"<=0.2")-L4-L3 -> 0 | M5: =COUNTIF(E3:E253,"<=0.2")-M4-M3 -> 0 | N5: =COUNTIF(F3:F253,"<=0.2")-N4-N3 -> 11
A6: =MCWaterSavings!B5/MCWaterBefore!B5 -> 0.48739496 | B6: =MCWaterSavings!C5/MCWaterBefore!C5 -> 0.38461538 | C6: =MCWaterSavings!D5/MCWaterBefore!D5 -> 0.4 | D6: =MCWaterSavings!E5/MCWaterBefore!E5 -> 0 | E6: =MCWaterSavings!F5/MCWaterBefore!F5 -> 0 | F6: =MCWaterSavings!G5/MCWaterBefore!G5 -> 0.26912975 | H6: 21% - 30% | I6: =COUNTIF(A3:A253,"<=0.3")-I4-I3-I5 -> 47 | J6: =COUNTIF(B3:B253,"<=0.3")-J4-J3-J5 -> 0 | K6: =COUNTIF(C3:C253,"<=0.3")-K4-K3-K5 -> 0 | L6: =COUNTIF(D3:D253,"<=0.3")-L4-L3-L5 -> 0 | M6: =COUNTIF(E3:E253,"<=0.3")-M4-M3-M5 -> 0 | N6: =COUNTIF(F3:F253,"<=0.3")-N4-N3-N5 -> 27
A7: =MCWaterSavings!B6/MCWaterBefore!B6 -> 0 | B7: =MCWaterSavings!C6/MCWaterBefore!C6 -> 0 | C7: =MCWaterSavings!D6/MCWaterBefore!D6 -> 0.4 | D7: =MCWaterSavings!E6/MCWaterBefore!E6 -> 0 | E7: =MCWaterSavings!F6/MCWaterBefore!F6 -> 0 | F7: =MCWaterSavings!G6/MCWaterBefore!G6 -> 0 | H7: 31% - 40% | I7: =COUNTIF(A3:A253,"<=0.4")-I4-I3-I5-I6 -> 59 | J7: =COUNTIF(B3:B253,"<=0.4")-J4-J3-J5-J6 -> 133 | K7: =COUNTIF(C3:C253,"<=0.4")-K4-K3-K5-K6 -> 137 | L7: =COUNTIF(D3:D253,"<=0.4")-L4-L3-L5-L6 -> 130 | M7: =COUNTIF(E3:E253,"<=0.4")-M4-M3-M5-M6 -> 121 | N7: =COUNTIF(F3:F253,"<=0.4")-N4-N3-N5-N6 -> 25
A8: =MCWaterSavings!B7/MCWaterBefore!B7 -> 0.25714286 | B8: =MCWaterSavings!C7/MCWaterBefore!C7 -> 0 | C8: =MCWaterSavings!D7/MCWaterBefore!D7 -> 0.4 | D8: =MCWaterSavings!E7/MCWaterBefore!E7 -> 0 | E8: =MCWaterSavings!F7/MCWaterBefore!F7 -> 0.4 | F8: =MCWaterSavings!G7/MCWaterBefore!G7 -> 0 | H8: 41% - 50% | I8: =COUNTIF(A3:A253,"<=0.5")-I4-I3-I5-I6-I7 -> 16 | J8: =COUNTIF(B3:B253,"<=0.5")-J4-J3-J5-J6-J7 -> 0 | K8: =COUNTIF(C3:C253,"<=0.5")-K4-K3-K5-K6-K7 -> 0 | L8: =COUNTIF(D3:D253,"<=0.5")-L4-L3-L5-L6-L7 -> 0 | M8: =COUNTIF(E3:E253,"<=0.5")-M4-M3-M5-M6-M7 -> 0 | N8: =COUNTIF(F3:F253,"<=0.5")-N4-N3-N5-N6-N7 -> 21
A9: =MCWaterSavings!B8/MCWaterBefore!B8 -> 0.4 | B9: =MCWaterSavings!C8/MCWaterBefore!C8 -> 0 | C9: =MCWaterSavings!D8/MCWaterBefore!D8 -> 0 | D9: =MCWaterSavings!E8/MCWaterBefore!E8 -> 0 | E9: =MCWaterSavings!F8/MCWaterBefore!F8 -> -1.638434e-16 | F9: =MCWaterSavings!G8/MCWaterBefore!G8 -> 0 | H9: 51% - 60% | I9: =COUNTIF(A3:A253,"<=0.6")-SUM(I3:I8) -> 35 | J9: =COUNTIF(B3:B253,"<=0.6")-SUM(J3:J8) -> 0 | K9: =COUNTIF(C3:C253,"<=0.6")-SUM(K3:K8) -> 58 | L9: =COUNTIF(D3:D253,"<=0.6")-SUM(L3:L8) -> 8 | M9: =COUNTIF(E3:E253,"<=0.6")-SUM(M3:M8) -> 0 | N9: =COUNTIF(F3:F253,"<=0.6")-SUM(N3:N8) -> 16
A10: =MCWaterSavings!B9/MCWaterBefore!B9 -> 0.74285714 | B10: =MCWaterSavings!C9/MCWaterBefore!C9 -> 0 | C10: =MCWaterSavings!D9/MCWaterBefore!D9 -> 0.59090909 | D10: =MCWaterSavings!E9/MCWaterBefore!E9 -> 0 | E10: =MCWaterSavings!F9/MCWaterBefore!F9 -> 0.4 | F10: =MCWaterSavings!G9/MCWaterBefore!G9 -> 0.65300979 | H10: 61% - 70% | I10: =COUNTIF(A3:A253,"<=0.7")-SUM(I3:I9) -> 25 | J10: =COUNTIF(B3:B253,"<=0.7")-SUM(J3:J9) -> 0 | K10: =COUNTIF(C3:C253,"<=0.7")-SUM(K3:K9) -> 0 | L10: =COUNTIF(D3:D253,"<=0.7")-SUM(L3:L9) -> 0 | M10: =COUNTIF(E3:E253,"<=0.7")-SUM(M3:M9) -> 0 | N10: =COUNTIF(F3:F253,"<=0.7")-SUM(N3:N9) -> 23
A11: =MCWaterSavings!B10/MCWaterBefore!B10 -> 1.7306402e-16 | B11: =MCWaterSavings!C10/MCWaterBefore!C10 -> 0 | C11: =MCWaterSavings!D10/MCWaterBefore!D10 -> 0.31818182 | D11: =MCWaterSavings!E10/MCWaterBefore!E10 -> 0.4 | E11: =MCWaterSavings!F10/MCWaterBefore!F10 -> 0.4 | F11: =MCWaterSavings!G10/MCWaterBefore!G10 -> 0.43140533 | H11: 71% - 80% | I11: =COUNTIF(A3:A253,"<=0.8")-SUM(I3:I10) -> 20 | J11: =COUNTIF(B3:B253,"<=0.8")-SUM(J3:J10) -> 0 | K11: =COUNTIF(C3:C253,"<=0.8")-SUM(K3:K10) -> 0 | L11: =COUNTIF(D3:D253,"<=0.8")-SUM(L3:L10) -> 0 | M11: =COUNTIF(E3:E253,"<=0.8")-SUM(M3:M10) -> 0 | N11: =COUNTIF(F3:F253,"<=0.8")-SUM(N3:N10) -> 0
A12: =MCWaterSavings!B11/MCWaterBefore!B11 -> 0.4 | B12: =MCWaterSavings!C11/MCWaterBefore!C11 -> 0.38461538 | C12: =MCWaterSavings!D11/MCWaterBefore!D11 -> 0.4 | D12: =MCWaterSavings!E11/MCWaterBefore!E11 -> 0 | E12: =MCWaterSavings!F11/MCWaterBefore!F11 -> 0.4 | F12: =MCWaterSavings!G11/MCWaterBefore!G11 -> 0 | H12: 81% - 90% | I12: =COUNTIF(A3:A253,"<=0.9")-SUM(I3:I11) -> 0 | J12: =COUNTIF(B3:B253,"<=0.9")-SUM(J3:J11) -> 0 | K12: =COUNTIF(C3:C253,"<=0.9")-SUM(K3:K11) -> 0 | L12: =COUNTIF(D3:D253,"<=0.9")-SUM(L3:L11) -> 0 | M12: =COUNTIF(E3:E253,"<=0.9")-SUM(M3:M11) -> 0 | N12: =COUNTIF(F3:F253,"<=0.9")-SUM(N3:N11) -> 0
A13: =MCWaterSavings!B12/MCWaterBefore!B12 -> 0.4 | B13: =MCWaterSavings!C12/MCWaterBefore!C12 -> 0.38461538 | C13: =MCWaterSavings!D12/MCWaterBefore!D12 -> 0.59090909 | D13: =MCWaterSavings!E12/MCWaterBefore!E12 -> 0 | E13: =MCWaterSavings!F12/MCWaterBefore!F12 -> 0 | F13: =MCWaterSavings!G12/MCWaterBefore!G12 -> 0.63944799 | I13: =SUM(I3:I12) -> 250 | J13: =SUM(J3:J12) -> 250 | K13: =SUM(K3:K12) -> 250 | L13: =SUM(L3:L12) -> 250 | M13: =SUM(M3:M12) -> 250 | N13: =SUM(N3:N12) -> 250
A14: =MCWaterSavings!B13/MCWaterBefore!B13 -> 0.73306122 | B14: =MCWaterSavings!C13/MCWaterBefore!C13 -> 0.38461538 | C14: =MCWaterSavings!D13/MCWaterBefore!D13 -> 0 | D14: =MCWaterSavings!E13/MCWaterBefore!E13 -> 0.4 | E14: =MCWaterSavings!F13/MCWaterBefore!F13 -> 0 | F14: =MCWaterSavings!G13/MCWaterBefore!G13 -> 0.27446311
A15: =MCWaterSavings!B14/MCWaterBefore!B14 -> 0.69090909 | B15: =MCWaterSavings!C14/MCWaterBefore!C14 -> 0.38461538 | C15: =MCWaterSavings!D14/MCWaterBefore!D14 -> 0.59090909 | D15: =MCWaterSavings!E14/MCWaterBefore!E14 -> 0.4 | E15: =MCWaterSavings!F14/MCWaterBefore!F14 -> -1.638434e-16 | F15: =MCWaterSavings!G14/MCWaterBefore!G14 -> 0.59286901
A16: =MCWaterSavings!B15/MCWaterBefore!B15 -> 0.4 | B16: =MCWaterSavings!C15/MCWaterBefore!C15 -> -1.7644674e-16 | C16: =MCWaterSavings!D15/MCWaterBefore!D15 -> 0.59090909 | D16: =MCWaterSavings!E15/MCWaterBefore!E15 -> 0.4 | E16: =MCWaterSavings!F15/MCWaterBefore!F15 -> 0.4 | F16: =MCWaterSavings!G15/MCWaterBefore!G15 -> 0
A17: =MCWaterSavings!B16/MCWaterBefore!B16 -> 0 | B17: =MCWaterSavings!C16/MCWaterBefore!C16 -> 0 | C17: =MCWaterSavings!D16/MCWaterBefore!D16 -> 1.6737113e-16 | D17: =MCWaterSavings!E16/MCWaterBefore!E16 -> 0.4 | E17: =MCWaterSavings!F16/MCWaterBefore!F16 -> 0 | F17: =MCWaterSavings!G16/MCWaterBefore!G16 -> 0
A18: =MCWaterSavings!B17/MCWaterBefore!B17 -> 0 | B18: =MCWaterSavings!C17/MCWaterBefore!C17 -> 0 | C18: =MCWaterSavings!D17/MCWaterBefore!D17 -> 0.59090909 | D18: =MCWaterSavings!E17/MCWaterBefore!E17 -> 0.4 | E18: =MCWaterSavings!F17/MCWaterBefore!F17 -> -1.638434e-16 | F18: =MCWaterSavings!G17/MCWaterBefore!G17 -> 0.65476472
A19: =MCWaterSavings!B18/MCWaterBefore!B18 -> 0.608 | B19: =MCWaterSavings!C18/MCWaterBefore!C18 -> 0.38461538 | C19: =MCWaterSavings!D18/MCWaterBefore!D18 -> 0.4 | D19: =MCWaterSavings!E18/MCWaterBefore!E18 -> 0 | E19: =MCWaterSavings!F18/MCWaterBefore!F18 -> 0 | F19: =MCWaterSavings!G18/MCWaterBefore!G18 -> 0.3641073
A20: =MCWaterSavings!B19/MCWaterBefore!B19 -> 0.10285714 | B20: =MCWaterSavings!C19/MCWaterBefore!C19 -> -1.6307956e-16 | C20: =MCWaterSavings!D19/MCWaterBefore!D19 -> 0 | D20: =MCWaterSavings!E19/MCWaterBefore!E19 -> 0.4 | E20: =MCWaterSavings!F19/MCWaterBefore!F19 -> 0.4 | F20: =MCWaterSavings!G19/MCWaterBefore!G19 -> 0.25500166
A21: =MCWaterSavings!B20/MCWaterBefore!B20 -> 0.28571429 | B21: =MCWaterSavings!C20/MCWaterBefore!C20 -> 0 | C21: =MCWaterSavings!D20/MCWaterBefore!D20 -> 2.2122097e-16 | D21: =MCWaterSavings!E20/MCWaterBefore!E20 -> 0 | E21: =MCWaterSavings!F20/MCWaterBefore!F20 -> 0 | F21: =MCWaterSavings!G20/MCWaterBefore!G20 -> 0
A22: =MCWaterSavings!B21/MCWaterBefore!B21 -> 0.4 | B22: =MCWaterSavings!C21/MCWaterBefore!C21 -> 0.38461538 | C22: =MCWaterSavings!D21/MCWaterBefore!D21 -> 0.31818182 | D22: =MCWaterSavings!E21/MCWaterBefore!E21 -> 0 | E22: =MCWaterSavings!F21/MCWaterBefore!F21 -> 0 | F22: =MCWaterSavings!G21/MCWaterBefore!G21 -> 0
A23: =MCWaterSavings!B22/MCWaterBefore!B22 -> 0.74285714 | B23: =MCWaterSavings!C22/MCWaterBefore!C22 -> 1.1450267e-16 | C23: =MCWaterSavings!D22/MCWaterBefore!D22 -> 0.4 | D23: =MCWaterSavings!E22/MCWaterBefore!E22 -> 0.4 | E23: =MCWaterSavings!F22/MCWaterBefore!F22 -> 0 | F23: =MCWaterSavings!G22/MCWaterBefore!G22 -> 0
A24: =MCWaterSavings!B23/MCWaterBefore!B23 -> 0.46666667 | B24: =MCWaterSavings!C23/MCWaterBefore!C23 -> 0.38461538 | C24: =MCWaterSavings!D23/MCWaterBefore!D23 -> 0.31818182 | D24: =MCWaterSavings!E23/MCWaterBefore!E23 -> 0 | E24: =MCWaterSavings!F23/MCWaterBefore!F23 -> 0.4 | F24: =MCWaterSavings!G23/MCWaterBefore!G23 -> 0
A25: =MCWaterSavings!B24/MCWaterBefore!B24 -> 0.28571429 | B25: =MCWaterSavings!C24/MCWaterBefore!C24 -> 0.38461538 | C25: =MCWaterSavings!D24/MCWaterBefore!D24 -> 0.31818182 | D25: =MCWaterSavings!E24/MCWaterBefore!E24 -> 0.4 | E25: =MCWaterSavings!F24/MCWaterBefore!F24 -> 0.4 | F25: =MCWaterSavings!G24/MCWaterBefore!G24 -> 0.28283865
... A252: =MCWaterSavings!B251/MCWaterBefore!B251 -> 0.43223443 | B252: =MCWaterSavings!C251/MCWaterBefore!C251 -> 0 | C252: =MCWaterSavings!D251/MCWaterBefore!D251 -> 0.59090909 | D252: =MCWaterSavings!E251/MCWaterBefore!E251 -> 0 | E252: =MCWaterSavings!F251/MCWaterBefore!F251 -> 0.4 | F252: =MCWaterSavings!G251/MCWaterBefore!G251 -> 0.30084663

Sheet Figures
A1: Action | B1: Times chosen
A2: LowFlowShower | B2: =COUNTIF(MCActionLong!B2:B240, 1) -> 111
A3: LowFLowToilet | B3: =COUNTIF(MCActionLong!C2:C240, 1) -> 133
A4: AeratorFaucet | B4: =COUNTIF(MCActionLong!D2:D240, 1) -> 126
A5: HELaundry | B5: =COUNTIF(MCActionLong!E2:E240, 1) -> 8
A6: HEDishwasher | B6: =COUNTIF(MCActionLong!F2:F240, 1) -> 0
A7: ShortShowers | B7: =COUNTIF(MCActionShort!B2:B245, ">0") -> 119
A8: LessShowers | B8: =COUNTIF(MCActionShort!C2:C245, ">0") -> 113
A9: LessFaucet | B9: =COUNTIF(MCActionShort!D2:D245, ">0") -> 127
A10: LessLaundry | B10: =COUNTIF(MCActionShort!E2:E245, ">0") -> 130
A11: LessDishLoads | B11: =COUNTIF(MCActionShort!F2:F245, ">0") -> 121
A12: OutdoorReduction | B12: =COUNTIF(MCOutdoorWilling!Q2:IP2, 1) -> 114
A18: End Use | B18: Before | C18: After | D18: Average Savings
A19: Shower | B19: =AVERAGE(MCWaterBefore!B2:B251) -> 546187.82 | C19: =AVERAGE(MCWaterAfter!B2:B251) -> 329748.43 | D19: =AVERAGE(MCWaterSavings!B2:B251) -> 248210.31
A20: Toilet | B20: =AVERAGE(MCWaterBefore!C2:C251) -> 88826.4 | C20: =AVERAGE(MCWaterAfter!C2:C251) -> 70526.56 | D20: =AVERAGE(MCWaterSavings!C2:C251) -> 25276.022
A21: Faucets | B21: =AVERAGE(MCWaterBefore!D2:D251) -> 91117.312 | C21: =AVERAGE(MCWaterAfter!D2:D251) -> 61003.28 | D21: =AVERAGE(MCWaterSavings!D2:D251) -> 35345.108
A22: Laundry | B22: =AVERAGE(MCWaterBefore!E2:E251) -> 76989.12 | C22: =AVERAGE(MCWaterAfter!E2:E251) -> 58512.896 | D22: =AVERAGE(MCWaterSavings!E2:E251) -> 33471.42
A23: Dishwasher | B23: =AVERAGE(MCWaterBefore!F2:F251) -> 17078.048 | C23: =AVERAGE(MCWaterAfter!F2:F251) -> 13799.469 | D23: =AVERAGE(MCWaterSavings!F2:F251) -> 5464.2987
A24: Outdoor | B24: =AVERAGE(MCWaterBefore!G2:G251) -> 623943.68 | C24: =AVERAGE(MCWaterAfter!G2:G251) -> 491959.11 | D24: =AVERAGE(MCWaterSavings!G2:G251) -> 261874.15

Sheet Summary
B1: ObjValue | C1: TotalWater_Current | D1: TotalWater_After | E1: InvestCost | K1: s1 | L1: s2 | M1: s3 | N1: s4 | O1: s5 | P1: s6 | Q1: s7 | R1: s8 | S1: s9 | T1: s10 | U1: s11 | V1: s12 | W1: s13 | X1: s14 | Y1: s15 | Z1: s16 | AA1: s17 | AB1: s18 | AC1: s19 | AD1: s20 | AE1: s21 | AF1: s22 | AG1: s23 | AH1: s24 | AI1: s25 | AJ1: s26 | AK1: s27 | AL1: s28 | AM1: s29 | AN1: s30 | AO1: s31 | AP1: s32 | AQ1: s33 | AR1: s34 | AS1: s35 | AT1: s36 | AU1: s37 | AV1: s38 | AW1: s39 | AX1: s40 | AY1: s41 | AZ1: s42 | BA1: s43 | BB1: s44 | BC1: s45 | BD1: s46 | BE1: s47 | BF1: s48 | BG1: s49 | BH1: s50 | BI1: s51 | BJ1: s52 | BK1: s53 | BL1: s54 | BM1: s55 | BN1: s56 | BO1: s57 | BP1: s58 | BQ1: s59 | BR1: s60 | BS1: s61 | BT1: s62 | BU1: s63 | BV1: s64 | BW1: s65 | BX1: s66 | BY1: s67 | BZ1: s68 | CA1: s69 | CB1: s70 | CC1: s71 | CD1: s72 | CE1: s73 | CF1: s74 | CG1: s75 | CH1: s76 | CI1: s77 | CJ1: s78 | CK1: s79 | CL1: s80 | CM1: s81 | CN1: s82 | CO1: s83 | CP1: s84 | CQ1: s85 | CR1: s86 | CS1: s87 | CT1: s88 | CU1: s89 | CV1: s90 | CW1: s91 | CX1: s92 | CY1: s93 | CZ1: s94 | DA1: s95 | DB1: s96 | DC1: s97 | DD1: s98 | DE1: s99 | DF1: s100 | DG1: s101 | DH1: s102 | DI1: s103 | DJ1: s104 | DK1: s105 | DL1: s106 | DM1: s107 | DN1: s108 | DO1: s109 | DP1: s110 | DQ1: s111 | DR1: s112 | DS1: s113 | DT1: s114 | DU1: s115 | DV1: s116 | DW1: s117 | DX1: s118 | DY1: s119 | DZ1: s120 | EA1: s121 | EB1: s122 | EC1: s123 | ED1: s124 | EE1: s125 | EF1: s126 | EG1: s127 | EH1: s128 | EI1: s129 | EJ1: s130 | EK1: s131 | EL1: s132 | EM1: s133 | EN1: s134 | EO1: s135 | EP1: s136 | EQ1: s137 | ER1: s138 | ES1: s139 | ET1: s140 | EU1: s141 | EV1: s142 | EW1: s143 | EX1: s144 | EY1: s145 | EZ1: s146 | FA1: s147 | FB1: s148 | FC1: s149 | FD1: s150 | FE1: s151 | FF1: s152 | FG1: s153 | FH1: s154 | FI1: s155 | FJ1: s156 | FK1: s157 | FL1: s158 | FM1: s159 | FN1: s160 | FO1: s161 | FP1: s162 | FQ1: s163 | FR1: s164 | FS1: s165 | FT1: s166 | FU1: s167 | FV1: s168 | FW1: s169 | FX1: s170 | FY1: s171 | FZ1: s172 | GA1: s173 | GB1: s174 | GC1: s175 | GD1: s176 | GE1: s177 | GF1: s178 | GG1: s179 | GH1: s180 | GI1: s181 | GJ1: s182 | GK1: s183 | GL1: s184 | GM1: s185 | GN1: s186 | GO1: s187 | GP1: s188 | GQ1: s189 | GR1: s190 | GS1: s191 | GT1: s192 | GU1: s193 | GV1: s194 | GW1: s195 | GX1: s196 | GY1: s197 | GZ1: s198 | HA1: s199 | HB1: s200 | HC1: s201 | HD1: s202 | HE1: s203 | HF1: s204 | HG1: s205 | HH1: s206 | HI1: s207 | HJ1: s208 | HK1: s209 | HL1: s210 | HM1: s211 | HN1: s212 | HO1: s213 | HP1: s214 | HQ1: s215 | HR1: s216 | HS1: s217 | HT1: s218 | HU1: s219 | HV1: s220 | HW1: s221 | HX1: s222 | HY1: s223 | HZ1: s224 | IA1: s225 | IB1: s226 | IC1: s227 | ID1: s228 | IE1: s229 | IF1: s230 | IG1: s231 | IH1: s232 | II1: s233 | IJ1: s234 | IK1: s235 | IL1: s236 | IM1: s237 | IN1: s238 | IO1: s239 | IP1: s240 | IQ1: s241 | IR1: s242 | IS1: s243 | IT1: s244 | IU1: s245 | IV1: s246 | IW1: s247 | IX1: s248 | IY1: s249 | IZ1: s250
A2: s1 | B2: 52960.954 | C2: 8090542.9 | D2: 7974541.3 | E2: 10 | K2: 770.25062 | L2: 7965.8168 | M2: 1037.6787 | N2: 4995.511 | O2: 2386.5754 | P2: 2241.0053 | Q2: 9682.5351 | R2: 9201.9882 | S2: 1936.0459 | T2: 7828.6854 | U2: 423.86573 | V2: 9774.7042 | W2: 3442.8699 | X2: 30287.962 | Y2: 18215.951 | Z2: 26096.475 | AA2: 42875.43 | AB2: 2226.5236 | AC2: 455.36332 | AD2: 46197.087 | AE2: 15035.093 | AF2: 4779.6351 | AG2: 51777.947 | AH2: 5291.2152 | AI2: 3985.0836 | AJ2: 5067.4702 | AK2: 996.47271 | AL2: 49314.561 | AM2: 7772.4514 | AN2: 45318.145 | AO2: 2443.4223 | AP2: 9276.0715 | AQ2: 2430.8264 | AR2: 17456.744 | AS2: 1504.7648 | AT2: 36146.788 | AU2: 15897.327 | AV2: 18962.421 | AW2: 29004.846 | AX2: 4642.5106 | AY2: 6029.5298 | AZ2: 33369.676 | BA2: 1371.4089 | BB2: 76861.452 | BC2: 24973.874 | BD2: 33527.443 | BE2: 8562.3363 | BF2: 1591.7546 | BG2: 2261.3906 | BH2: 4225.7128 | BI2: 17711.495 | BJ2: 2968.4274 | BK2: 24551.5 | BL2: 19531.516 | BM2: 902.1393 | BN2: 4561.5286 | BO2: 3093.1881 | BP2: 12427.197 | BQ2: 3587.8909 | BR2: 7393.1769 | BS2: 24624.381 | BT2: 1271.4591 | BU2: 23899.025 | BV2: 11738.554 | BW2: 18418.975 | BX2: 6126.813 | BY2: 27149.98 | BZ2: 8490.2971 | CA2: 10235.838 | CB2: 3675.7133 | CC2: 3240.1075 | CD2: 9283.2229 | CE2: 43467.029 | CF2: 58247.786 | CG2: 3120.0606 | CH2: 2974.7667 | CI2: 7322.3261 | CJ2: 1366.6285 | CK2: 6470.4484 | CL2: 5002.9009 | CM2: 5589.9133 | CN2: 23955.518 | CO2: 3604.5414 | CP2: 7693.0246 | CQ2: 1609.4343 | CR2: 3682.0659 | CS2: 5292.3373 | CT2: 21958.234 | CU2: 8365.2532 | CV2: 22939.24 | CW2: 3267.2297 | CX2: 9199.3125 | CY2: 9767.779 | CZ2: 3398.4294 | DA2: 2662.7616 | DB2: 12483.806 | DC2: 5479.7317 | DD2: 19457.08 | DE2: 19467.805 | DF2: 15040.826 | DG2: 8344.8099 | DH2: 4755.9012 | DI2: 1620.3852 | DJ2: 22403.838 | DK2: 1238.2381 | DL2: 10530.282 | DM2: 3088.571 | DN2: 39743.287 | DO2: 3218.3234 | DP2: 36059.685 | DQ2: 53955.745 | DR2: 2392.0998 | DS2: 4098.4004 | DT2: 58192.415 | DU2: 5110.1315 | DV2: 1611.7127 | DW2: 9734.9624 | DX2: 5727.2837 | DY2: 47823.749 | DZ2: 7576.8243 | EA2: 8322.5383 | EB2: 6061.8393 | EC2: 13304.743 | ED2: 28655.795 | EE2: 40187.31 | EF2: 40215.59 | EG2: 5814.308 | EH2: 7248.1178 | EI2: 47184.584 | EJ2: 44684.359 | EK2: 8550.6998 | EL2: 5066.5075 | EM2: 64341.394 | EN2: 67955.295 | EO2: 502.72333 | EP2: 2967.3606 | EQ2: 17018.722 | ER2: 1840.8534 | ES2: 5454.3605 | ET2: 45094.206 | EU2: 2865.7135 | EV2: 20697.976 | EW2: 34180.259 | EX2: 3221.1738 | EY2: 8641.7208 | EZ2: 29961.962 | FA2: 18474.164 | FB2: 4981.1474 | FC2: 8119.3227 | FD2: 4320.7027 | FE2: 26037.591 | FF2: 25134.519 | FG2: 42873.763 | FH2: 18016.02 | FI2: 2315.5215 | FJ2: 14849.463 | FK2: 29011.486 | FL2: 9596.9084 | FM2: 1703.3353 | FN2: 45826.904 | FO2: 5186.9619 | FP2: 735.58451 | FQ2: 7301.9262 | FR2: 6348.1703 | FS2: 629.97525 | FT2: 1878.288 | FU2: 275.17435 | FV2: 7404.3224 | FW2: 2986.23 | FX2: 8075.2429 | FY2: 5229.5048 | FZ2: 4691.5265 | GA2: 3403.7758 | GB2: 6090.4171 | GC2: 36047.199 | GD2: 3726.7037 | GE2: 9277.8117 | GF2: 11607.416 | GG2: 58398.578 | GH2: 5534.6552 | GI2: 2547.0615 | GJ2: 14181.677 | GK2: 45860.034 | GL2: 37351.547 | GM2: 5909.3618 | GN2: 830.05312 | GO2: 3277.8121 | GP2: 46300.464 | GQ2: 507.42047 | GR2: 299.20584 | GS2: 211.43566 | GT2: 716.09691 | GU2: 22758.869 | GV2: 12805.717 | GW2: 16705.002 | GX2: 5567.645 | GY2: 7267.1082 | GZ2: 4001.6099 | HA2: 18563.132 | HB2: 2041.9652 | HC2: 20398.729 | HD2: 4982.5976 | HE2: 1610.5464 | HF2: 17824.45 | HG2: 7753.7936 | HH2: 18930.017 | HI2: 50257.034 | HJ2: 4389.7945 | HK2: 2788.3656 | HL2: 1367.6048 | HM2: 18438.504 | HN2: 3814.7916 | HO2: 1934.1204 | HP2: 391.96186 | HQ2: 1540.088 | HR2: 32176.905 | HS2: 2688.212 | HT2: 4654.3606 | HU2: 9786.9167 | HV2: 15160.22 | HW2: 6790.4026 | HX2: 21171.575 | HY2: 23120.57 | HZ2: 23652.15 | IA2: 819.63948 | IB2: 18100.406 | IC2: 13074.29 | ID2: 49137.266 | IE2: 4797.1905 | IF2: 1229.5421 | IG2: 38815.013 | IH2: 6790.7842 | II2: 37792.415 | IJ2: 4002.03 | IK2: 19334.288 | IL2: 9486.1813 | IM2: 547.58646 | IN2: 1591.7132 | IO2: 48150.677 | IP2: 4961.5355 | IQ2: 25399.46 | IR2: 7789.9311 | IS2: 15547.267 | IT2: 23046.736 | IU2: 4382.639 | IV2: 6001.5741 | IW2: 8206.615 | IX2: 4004.1149 | IY2: 7955.8036 | IZ2: 1651.2671
A3: s2 | B3: 16836.627 | C3: 3622356 | D3: 2422684.8 | E3: 750
A4: s3 | B4: 3901.9531 | C4: 683679.48 | D4: 527402.57 | E4: 400
A5: s4 | B5: 9863.2631 | C5: 2168490.1 | D5: 1416154.1 | E5: 460
A6: s5 | B6: 4539.9227 | C6: 982906.33 | D6: 623482.33 | E6: 400
A7: s6 | B7: 28220.273 | C7: 4570975.7 | D7: 4233474.9 | E7: 110
A8: s7 | B8: 18625.65 | C8: 4203039.9 | D8: 2744826.8 | E8: 400
A9: s8 | B9: 11265.667 | C9: 3020731.2 | D9: 1634889.6 | E9: 410
A10: s9 | B10: 3063.5437 | C10: 638492.41 | D10: 346919.23 | E10: 760
A11: s10 | B11: 5942.5913 | C11: 2013746.5 | D11: 834727.6 | E11: 400
A12: s11 | B12: 14958.815 | C12: 2307632.7 | D12: 2243797.5 | E12: 60
A13: s12 | B13: 27473.069 | C13: 5591532.1 | D13: 4119438.1 | E13: 120
A14: s13 | B14: 5810.9845 | C14: 1280701 | D14: 762196.46 | E14: 750
... A85: s84 | B85: 5287.8103 | C85: 1831451 | D85: 672862.99 | E85: 820
A86: s85 | B86: 10013.312 | C86: 1750413.6 | D86: 1508028.9
A87: s86 | B87: 5071.6743 | C87: 1211406.7 | D87: 656878.66 | E87: 710
A88: s87 | B88: 5256.9135 | C88: 1465248.6 | D88: 668209.86 | E88: 820
A89: s88 | B89: 17035.002 | C89: 5803198.1 | D89: 2496235.3 | E89: 460
A90: s89 | B90: 11539.201 | C90: 2937417.9 | D90: 1677590.6 | E90: 400
A91: s90 | B91: 16974.244 | C91: 5889078.9 | D91: 2434374.1 | E91: 810
A92: s91 | B92: 37015.664 | C92: 6010978 | D92: 5518925.3 | E92: 370
A93: s92 | B93: 15587.663 | C93: 3732978.3 | D93: 2347539.7
A94: s93 | B94: 46295.583 | C94: 8380024.4 | D94: 6908973.4 | E94: 420
A95: s94 | B95: 34232.994 | C95: 5614672.2 | D95: 5102860.5 | E95: 350
A96: s95 | B96: 5644.758 | C96: 1198421.6 | D96: 797403.31 | E96: 350
A97: s96 | B97: 6211.3195 | C97: 2737217.6 | D97: 857126.44 | E97: 520
A98: s97 | B98: 11256.615 | C98: 2475353.4 | D98: 1650092.6 | E98: 300
A99: s98 | B99: 14944.423 | C99: 5102636.1 | D99: 2172352.9 | E99: 520
A100: s99 | B100: 21381.885 | C100: 6036097.9 | D100: 3104199.5 | E100: 770
A101: s100 | B101: 17204.506 | C101: 4786947.6 | D101: 2521763 | E101: 460
A102: s101 | B102: 15019.373 | C102: 3518702.2 | D102: 2261953.7
A103: s102 | B103: 5505.3697 | C103: 1474589 | D103: 758338.8 | E103: 470
A104: s103 | B104: 8528.6367 | C104: 1511900.9 | D104: 1267867 | E104: 110
A105: s104 | B105: 36481.32 | C105: 8804993.7 | D105: 5430921.7 | E105: 420
A106: s105 | B106: 3306.0158 | C106: 631664.75 | D106: 445183.1 | E106: 350
A107: s106 | B107: 9908.7634 | C107: 3016422.5 | D107: 1430536.7 | E107: 410
A108: s107 | B108: 5834.3766 | C108: 1273034.3 | D108: 807888.04 | E108: 470
A109: s108 | B109: 24307.784 | C109: 9586004.6 | D109: 3600569.8 | E109: 400
A110: s109 | B110: 25009.87 | C110: 4233161.7 | D110: 3748474.4 | E110: 120
...

Sheet SavingsBreakdown
B1: Shower | C1: Toilet | D1: Faucets | E1: Laundry | F1: Dishwasher | G1: Outdoor
A2: s1 | B2: 78936 | C2: 2.3283064e-10 | D2: 37065.6
A3: s2 | D3: 73382.4 | E3: 1002456 | F3: 123832.8
A4: s3 | B4: 2620.8 | D4: 2196.48 | E4: 101088 | G4: 50371.628
A5: s4 | C5: 21840 | D5: 59488 | E5: 468000 | F5: 203008
A6: s5 | E6: 359424 | F6: -2.910383e-11
A7: s6 | B7: 48921.6 | C7: 211120 | D7: 77459.2
A8: s7 | B8: 1.1641532e-10 | D8: 43929.6 | E8: 741312 | F8: 672971.52
A9: s8 | B9: 63336 | D9: 160617.6 | E9: 1085760 | F9: 76128
A10: s9 | B10: 27518.4 | C10: 65520 | D10: 1281.28 | E10: 123552 | F10: 67704 | G10: 5997.4955
A11: s10 | B11: 69189.12 | C11: -2.910383e-11 | D11: 7321.6 | E11: 1085760 | F11: 16748.16
A12: s11 | B12: 22464 | C12: -2.910383e-11 | D12: 41371.2 | F12: -1.4551915e-11
A13: s12 | B13: 141523.2 | C13: 16380 | D13: 472726.8 | E13: 841464 | F13: -4.6566129e-10
A14: s13 | B14: 960.96 | C14: -2.910383e-11 | D14: 74360 | E14: 262080 | F14: 141086.4 | G14: 40017.143
A15: s14 | B15: 1.1641532e-10 | C15: 68640 | D15: 82368 | E15: 4410432 | F15: -1.1641532e-10
A16: s15 | B16: 45864 | C16: 61880 | D16: 5.8207661e-11 | E16: 2584108.8 | F16: 51513.28
A17: s16 | B17: 29484 | C17: -5.8207661e-11 | D17: 10982.4 | E17: 3420144 | F17: 383685.12 | G17: 85896.549
A18: s17 | B18: 117936 | D18: 104832 | E18: 6177600 | G18: 56775.136
A19: s18 | B19: 21141.12 | C19: 96096 | D19: 100855.04 | F19: 67267.2 | G19: 49960.455
A20: s19 | B20: 37346.4 | G20: 31232.414
A21: s20 | B21: 141523.2 | C21: 243360 | E21: 5896800 | F21: 470995.2 | G21: 204714.24
A22: s21 | B22: 51367.68 | C22: 114816 | E22: 1824076.8 | F22: 274060.8
A23: s22 | B23: 68739.84 | C23: 28392 | D23: 1647.36 | E23: 437923.2 | F23: 146031.6 | G23: 37090.566
A24: s23 | B24: 98560.8 | C24: -7.2759576e-12 | D24: 20638.8 | E24: 7426598.4 | F24: 97063.2 | G24: 155022.34
A25: s24 | C25: -7.2759576e-12 | D25: 83959.2 | E25: 577740.8 | F25: 85263.36 | G25: 49906.398
A26: s25 | B26: 23587.2 | C26: -3.6379788e-12 | E26: 576576
A27: s26 | B27: 2673.216 | E27: 580320 | F27: 180180
A28: s27 | B28: 20161.44 | C28: 1.1641532e-10 | D28: 51105.6 | E28: 25147.2 | F28: 11419.2 | G28: 42237.751
A29: s28 | B29: 268632 | C29: 95472 | D29: 135358.08 | E29: 6840288 | F29: 87141.6
A30: s29 | B30: 5.8207661e-11 | D30: 39811.2 | E30: 973440 | F30: 128783.2 | G30: 28515.506
A31: s30 | B31: 262211.04 | D31: 140540.4 | E31: 5016211.2 | F31: 1406059.2
A32: s31 | B32: 127576.8 | D32: 53676.48 | F32: 186732
A33: s32 | B33: 3120 | D33: 44478.72 | E33: 1042329.6 | F33: 307070.4
A34: s33 | B34: 37440 | C34: 22880 | D34: 36241.92 | E34: 269526.4
A35: s34 | C35: -5.8207661e-11 | E35: 2515968 | F35: -1.4551915e-11 | G35: 113059.77
A36: s35 | B36: 53539.2 | D36: 109200 | F36: 63882
A37: s36 | B37: 69896.736 | D37: 1.1641532e-10 | E37: 5016211.2 | F37: 64209.6 | G37: 293475.87
A38: s37 | B38: 586310.4 | C38: 1.1641532e-10 | E38: 1769040 | F38: 38825.28
A39: s38 | B39: 125798.4 | C39: 145600 | D39: 10982.4 | E39: 2493504 | G39: 79901.549
A40: s39 | B40: 419328 | D40: 37889.28 | E40: 3412281.6 | F40: 498700.8
...

Sheet OutdoorDetails
A1: s3 | B1: s9 | C1: s13 | D1: s16 | E1: s17 | F1: s18 | G1: s19 | H1: s20 | I1: s22 | J1: s23 | K1: s24 | L1: s27 | M1: s29 | N1: s34 | O1: s36 | P1: s38 | Q1: s41 | R1: s42 | S1: s43 | T1: s44 | U1: s45 | V1: s46 | W1: s50 | X1: s51 | Y1: s53 | Z1: s54 | AA1: s58 | AB1: s59 | AC1: s60 | AD1: s61 | AE1: s64 | AF1: s66 | AG1: s69 | AH1: s70 | AI1: s72 | AJ1: s74 | AK1: s77 | AL1: s78 | AM1: s79 | AN1: s80 | AO1: s81 | AP1: s82 | AQ1: s83 | AR1: s84 | AS1: s85 | AT1: s87 | AU1: s90 | AV1: s91 | AW1: s92 | AX1: s93 | AY1: s95 | AZ1: s100 | BA1: s102 | BB1: s105 | BC1: s106 | BD1: s108 | BE1: s109 | BF1: s110 | BG1: s113 | BH1: s114 | BI1: s115 | BJ1: s116 | BK1: s119 | BL1: s121 | BM1: s124 | BN1: s125 | BO1: s130 | BP1: s131 | BQ1: s133 | BR1: s134 | BS1: s135 | BT1: s136 | BU1: s137 | BV1: s140 | BW1: s142 | BX1: s143 | BY1: s144 | BZ1: s145 | CA1: s147 | CB1: s151 | CC1: s153 | CD1: s155 | CE1: s156 | CF1: s157 | CG1: s160 | CH1: s165 | CI1: s166 | CJ1: s171 | CK1: s173 | CL1: s174 | CM1: s175 | CN1: s179 | CO1: s180 | CP1: s184 | CQ1: s185 | CR1: s188 | CS1: s189 | CT1: s195 | CU1: s196 | CV1: s198 | CW1: s199 | CX1: s201 | CY1: s203 | CZ1: s204 | DA1: s205 | DB1: s207 | DC1: s208 | DD1: s209 | DE1: s210 | DF1: s215 | DG1: s216 | DH1: s219 | DI1: s220 | DJ1: s221 | DK1: s231 | DL1: s232 | DM1: s236 | DN1: s243 | DO1: s248
A2: 50371.628 | B2: 5997.4955 | C2: 40017.143 | D2: 85896.549 | E2: 56775.136 | F2: 49960.455 | G2: 31232.414 | H2: 204714.24 | I2: 37090.566 | J2: 155022.34 | K2: 49906.398 | L2: 42237.751 | M2: 28515.506 | N2: 113059.77 | O2: 293475.87 | P2: 79901.549 | Q2: 68963.714 | R2: 141738.59 | S2: 114343.56 | T2: 191729.87 | U2: 109943.52 | V2: 139011.9 | W2: 59083.973 | X2: 69615.296 | Y2: 164202.46 | Z2: 235423.81 | AA2: 259156 | AB2: 27721.736 | AC2: 80866.25 | AD2: 161735 | AE2: 16211.593 | AF2: 85918.405 | AG2: 424057.65 | AH2: 245128.08 | AI2: 96401.337 | AJ2: 246295.35 | AK2: 237546.51 | AL2: 60877.948 | AM2: 251138.87 | AN2: 46244.766 | AO2: 90662.409 | AP2: 39861.866 | AQ2: 161759.18 | AR2: 142840.84 | AS2: 26526.441 | AT2: 26981.148 | AU2: 91388.514 | AV2: 239051.87 | AW2: 63007.914 | AX2: 245171.85 | AY2: 29067.519 | AZ2: 49643.497 | BA2: 60226.499 | BB2: 17388.046 | BC2: 93477.512 | BD2: 253271.95 | BE2: 215905.5 | BF2: 360974.9 | BG2: 11399.863 | BH2: 211440.5 | BI2: 120596.52 | BJ2: 67184.143 | BK2: 195822.18 | BL2: 76746.641 | BM2: 99704.739 | BN2: 89394.954 | BO2: 71467.162 | BP2: 92088.789 | BQ2: 165544.92 | BR2: 156880.75 | BS2: 16406.385 | BT2: 18699.527 | BU2: 199899.74 | BV2: 50991.166 | BW2: 106281.87 | BX2: 52627.759 | BY2: 152366.46 | BZ2: 43147.172 | CA2: 110651.7 | CB2: 183114.63 | CC2: 60446.887 | CD2: 99091.916 | CE2: 141815.34 | CF2: 101039.77 | CG2: 253608.56 | CH2: 13526.99 | CI2: 39493.904 | CJ2: 176180.82 | CK2: 166099.23 | CL2: 74149.249 | CM2: 124550.7 | CN2: 138959.16 | CO2: 21096.89 | CP2: 114476.81 | CQ2: 220682.52 | CR2: 366569.38 | CS2: 14167.466 | CT2: 160047.13 | CU2: 37964.293 | CV2: 24759.448 | CW2: 298760.07 | CX2: 85732.543 | CY2: 165893.77 | CZ2: 82063.102 | DA2: 117787.2 | DB2: 132859.62 | DC2: 288242.43 | DD2: 20135.706 | DE2: 122098.98 | DF2: 180835.36 | DG2: 111399.14 | DH2: 106499.63 | DI2: 361734.52 | DJ2: 75552.119 | DK2: 200015.35 | DL2: 127918.46 | DM2: 91072.809 | DN2: 121638.31 | DO2: 140062.95

Sheet WaterBefore
B1: Shower | C1: Toilet | D1: Faucets | E1: Laundry | F1: Dishwasher | G1: Outdoor
A2: s1 | B2: 144144 | C2: 1370928 | D2: 92664 | E2: 4384640 | F2: 1522560 | G2: 575606.92
A3: s2 | B3: 53508 | C3: 817689.6 | D3: 230630.4 | E3: 1726452 | F3: 359704.8 | G3: 434371.21
A4: s3 | B4: 6552 | C4: 103833.6 | D4: 5491.2 | E4: 174096 | F4: 314662.4 | G4: 79044.275
A5: s4 | B5: 191100 | C5: 56784 | D5: 148720 | E5: 806000 | F5: 507520 | G5: 458366.07
A6: s5 | B6: 85176 | C6: 18928 | D6: 57657.6 | E6: 619008 | F6: 62805.6 | G6: 139331.13
A7: s6 | B7: 110838 | C7: 548912 | D7: 243443.2 | E7: 1308944 | F7: 2131584 | G7: 227254.48
A8: s7 | B8: 943488 | C8: 11897.6 | D8: 109824 | E8: 1276704 | F8: 1682428.8 | G8: 178697.51
A9: s8 | B9: 110838 | C9: 37180 | D9: 401544 | E9: 1869920 | F9: 190320 | G9: 410929.23
A10: s9 | B10: 27518.4 | C10: 170352 | D10: 3203.2 | E10: 212784 | F10: 196664 | G10: 27970.808
A11: s10 | B11: 172972.8 | C11: 231192 | D11: 18304 | E11: 1450800 | F11: 41870.4 | G11: 98607.279
A12: s11 | B12: 39312 | C12: 174137.6 | D12: 70012.8 | E12: 1740960 | F12: 96428.8 | G12: 186781.5
A13: s12 | B13: 247665.6 | C13: 42588 | D13: 799999.2 | E13: 2103660 | F13: 1918425.6 | G13: 479193.67
... A251: s250 | B251: 129292.8 | C251: 150883.2 | D251: 112112 | E251: 128960 | F251: 380640 | G251: 91496.215

Sheet WaterAfter
B1: Shower | C1: Toilet | D1: Faucets | E1: Laundry | F1: Dishwasher | G1: Outdoor
A2: s1 | B2: 65208 | C2: 1370928 | D2: 55598.4 | E2: 4384640 | F2: 1522560 | G2: 575606.92
A3: s2 | B3: 53508 | C3: 817689.6 | D3: 157248 | E3: 723996 | F3: 235872 | G3: 434371.21
A4: s3 | B4: 3931.2 | C4: 103833.6 | D4: 3294.72 | E4: 73008 | F4: 314662.4 | G4: 28672.648
A5: s4 | B5: 191100 | C5: 34944 | D5: 89232 | E5: 338000 | F5: 304512 | G5: 458366.07
A6: s5 | B6: 85176 | C6: 18928 | D6: 57657.6 | E6: 259584 | F6: 62805.6 | G6: 139331.13
A7: s6 | B7: 61916.4 | C7: 337792 | D7: 165984 | E7: 1308944 | F7: 2131584 | G7: 227254.48
A8: s7 | B8: 943488 | C8: 11897.6 | D8: 65894.4 | E8: 535392 | F8: 1009457.3 | G8: 178697.51
A9: s8 | B9: 47502 | C9: 37180 | D9: 240926.4 | E9: 784160 | F9: 114192 | G9: 410929.23
A10: s9 | C10: 104832 | D10: 1921.92 | E10: 89232 | F10: 128960 | G10: 21973.312
A11: s10 | B11: 103783.68 | C11: 231192 | D11: 10982.4 | E11: 365040 | F11: 25122.24 | G11: 98607.279
A12: s11 | B12: 16848 | C12: 174137.6 | D12: 28641.6 | E12: 1740960 | F12: 96428.8 | G12: 186781.5
A13: s12 | B13: 106142.4 | C13: 26208 | D13: 327272.4 | E13: 1262196 | F13: 1918425.6 | G13: 479193.67
A14: s13 | B14: 1441.44 | C14: 232003.2 | D14: 51480 | E14: 189280 | F14: 268736 | G14: 19255.817
A15: s14 | B15: 383292 | C15: 109824 | D15: 123552 | E15: 6615648 | F15: 754936 | G15: 720407.38
A16: s15 | B16: 34398 | C16: 99008 | D16: 331531.2 | E16: 868795.2 | F16: 77269.92 | G16: 497663.69
A17: s16 | B17: 9828 | C17: 249849.6 | D17: 16473.6 | E17: 1149876 | F17: 575527.68 | G17: 120945.02
A18: s17 | C18: 873392 | D18: 224640 | E18: 4461600 | F18: 570960 | G18: 156068.99
A19: s18 | B19: 2882.88 | C19: 153753.6 | D19: 151282.56 | E19: 3191760 | F19: 128128 | G19: 47782.95
A20: s19 | B20: 53944.8 | C20: 2704 | D20: 20134.4 | E20: 38688 | F20: 106579.2 | G20: 30722.578
A21: s20 | B21: 106142.4 | C21: 389376 | D21: 135907.2 | E21: 4258800 | F21: 305510.4 | G21: 120766.83
A22: s21 | B22: 324717.12 | C22: 183705.6 | D22: 37065.6 | E22: 613267.2 | F22: 411091.2 | G22: 370514.76
A23: s22 | B23: 19712.16 | C23: 45427.2 | D23: 2471.04 | E23: 147232.8 | F23: 94723.2 | G23: 138299.28
A24: s23 | B24: 246402 | C24: 52322.4 | D24: 44226 | E24: 2496873.6 | F24: 145594.8 | G24: 129731.99
A25: s24 | B25: 207916.8 | C25: 12979.2 | D25: 58125.6 | E25: 866611.2 | F25: 127895.04 | G25: 34188.542
A26: s25 | B26: 58968 | C26: 20550.4 | D26: 109824 | E26: 416416 | F26: 116729.6 | G26: 120266.92
A27: s26 | B27: 3223.584 | C27: 136281.6 | D27: 189446.4 | E27: 870480 | F27: 343200 | G27: 71477.465
A28: s27 | B28: 14236.56 | C28: 442915.2 | D28: 35380.8 | E28: 37720.8 | F28: 17128.8 | G28: 44004.842
A29: s28 | B29: 402948 | C29: 152755.2 | D29: 203037.12 | E29: 2299752 | F29: 165984 | G29: 223820.68
A30: s29 | B30: 32104.8 | C30: 8112 | D30: 59716.8 | E30: 703040 | F30: 193174.8 | G30: 50866.936
... A97: s96 | B97: 21060 | C97: 29286.4 | D97: 27144 | E97: 592987.2 | F97: 72321.6 | G97: 114327.24
A98: s97 | C98: 533228.8 | D98: 9152 | E98: 735072 | F98: 143769.6 | G98: 228870.19
A99: s98 | B99: 63460.8 | C99: 67392 | D99: 28080 | E99: 932880 | F99: 802516 | G99: 278024.07
A100: s99 | B100: 152755.2 | C100: 584064 | D100: 573281.28 | E100: 562161.6 | F100: 668304 | G100: 563633.45
A101: s100 | B101: 459950.4 | C101: 186368 | D101: 107078.4 | E101: 1335776 | F101: 267209.28 | G101: 165380.9
A102: s101 | B102: 78624 | C102: 220646.4 | D102: 9266.4 | E102: 1410177.6 | F102: 298041.12 | G102: 245198.21
A103: s102 | B103: 5110.56 | C103: 34944 | D103: 88957.44 | E103: 210912 | F103: 380830.32 | G103: 37584.484
A104: s103 | B104: 204422.4 | C104: 53913.6 | D104: 28080 | E104: 677040 | F104: 50244.48 | G104: 254166.5
A105: s104 | B105: 402948 | C105: 239616 | D105: 98280 | E105: 2978976 | F105: 1064960 | G105: 646141.66
A106: s105 | B106: 95550 | C106: 7030.4 | D106: 31636.8 | E106: 64480 | F106: 183040 | G106: 63445.904
...

Sheet LongTermActions
B1: LowFlowShower | C1: LowFLowToilet | D1: AeratorFaucet | E1: HELaundry | F1: HEDishwasher
A2: s1 | B2: 1
A3: s2 | D3: 1 | E3: 1 | F3: 1
A4: s3 | E4: 1
A5: s4 | C5: 1 | E5: 1
A6: s5 | E6: 1
A7: s6 | C7: 1 | D7: 1
A8: s7 | C8: 5.56509e-15 | E8: 1
A9: s8 | B9: 1 | E9: 1
A10: s9 | C10: 1 | E10: 1 | F10: 1
A11: s10 | E11: 1
A12: s11 | B12: 1 | D12: 1
A13: s12 | B13: 1 | C13: 1 | D13: 1
A14: s13 | D14: 1 | E14: 1 | F14: 1
A15: s14 | C15: 1
A16: s15 | B16: 1 | C16: 1 | E16: 1
A17: s16 | E17: 1
A18: s17 | D18: 1 | E18: 1
A19: s18 | C19: 1 | F19: 1
A20: s19 | B20: 1 | D20: 1.1357326e-15
A21: s20 | B21: 1 | C21: 1 | E21: 1 | F21: 1
A22: s21 | C22: 1 | E22: 1
A23: s22 | B23: 1 | C23: 1 | E23: 1 | F23: 1
A24: s23 | B24: 1 | D24: 1 | E24: 1
A25: s24 | D25: 1
A26: s25 | B26: 1 | E26: 1
A27: s26 | F27: 1
A28: s27 | B28: 1 | D28: 1
A29: s28 | C29: 1 | E29: 1 | F29: 1
A30: s29 | C30: 5.8300942e-16 | E30: 1
A31: s30 | B31: 1 | D31: 1 | E31: 1 | F31: 1
A32: s31 | B32: 1 | F32: 1
A33: s32 | B33: 1 | E33: 1 | F33: 1
A34: s33 | B34: 1 | C34: 1
A35: s34 | E35: 1
A36: s35 | B36: 1 | D36: 1 | F36: 1
A37: s36 | E37: 1 | F37: 1
A38: s37 | B38: 1 | E38: 1
A39: s38 | C39: 1 | E39: 1
A40: s39 | B40: 1 | F40: 1
...

Sheet ShortTermActions
B1: ShortShowers | C1: LessShowers | D1: LessFaucet | E1: LessLaundry | F1: LessDishLoads
A2: s1 | B2: 4.4 | D2: 1.2
A3: s3 | C3: 0.4 | D3: 1.2
A4: s4 | D4: 4 | F4: 4
A5: s6 | B5: 2 | C5: 2
A6: s7 | D6: 2.4 | F6: 6.8
A7: s8 | C7: 11.6 | D7: 7.2 | F7: 8
A8: s9 | B8: 11.2 | C8: 11.2 | D8: 0.4
A9: s10 | C9: 9.6 | D9: 0.8 | E9: 6 | F9: 0.8
A10: s11 | C10: 2 | D10: 3.6
A11: s12 | C11: 11.2 | D11: 8.4 | E11: 11.6
A12: s13 | C12: 0.4 | D12: 8.8
A13: s14 | D13: 1.6 | E13: 7.2
A14: s15 | C14: 2 | E14: 3.6 | F14: 0.8
A15: s16 | B15: 6 | D15: 6.4 | E15: 10.8 | F15: 9.6
A16: s17 | B16: 6
A17: s18 | B17: 4.4 | D17: 11.6
A18: s19 | B18: 7.6
A19: s20 | C19: 4.8 | F19: 6.4
A20: s21 | B20: 5.6 | E20: 2.4 | F20: 8
A21: s22 | B21: 7.2 | C21: 7.2 | D21: 0.8 | E21: 4.4 | F21: 4.4
A22: s23 | E22: 7.2 | F22: 6.8
A23: s24 | D23: 10.8 | E23: 5.6 | F23: 5.6
A24: s26 | B24: 0.8 | C24: 0.8 | E24: 12
A25: s27 | B25: 1.2 | C25: 1.2 | D25: 5.6 | E25: 0.4 | F25: 2
A26: s28 | C26: 10 | D26: 11.6 | E26: 8.4
A27: s29 | D27: 11.6 | F27: 11.6
A28: s30 | B28: 11.6 | C28: 11.6 | D28: 10.8 | E28: 10.8 | F28: 11.6
A29: s31 | B29: 11.6 | D29: 9.2
A30: s32 | D30: 7.2 | E30: 7.2 | F30: 7.6
A31: s33 | C31: 8 | D31: 7.2 | E31: 7.6
A32: s35 | B32: 4.4
A33: s36 | B33: 3.6 | C33: 3.6 | E33: 7.2
A34: s37 | C34: 11.6 | F34: 0.8
A35: s38 | C35: 7.2 | D35: 1.2
A36: s39 | C36: 11.2 | D36: 9.2 | E36: 8.4 | F36: 6.4
A37: s40 | D37: 12 | F37: 1.6
A38: s41 | C38: 1.6 | D38: 11.6 | F38: 4.4
A39: s42 | B39: 3.6 | E39: 10.8 | F39: 2.8
A40: s43 | B40: 1.2 | C40: 1.2 | D40: 6.8 | F40: 6.8
...

Sheet WillingLong
B1: LowFlowShower | C1: LowFLowToilet | D1: AeratorFaucet | E1: HELaundry | F1: HEDishwasher
A2: s1 | B2: 1
A3: s2 | D3: 1 | E3: 1 | F3: 1
A4: s3 | E4: 1
A5: s4 | C5: 1 | E5: 1
A6: s5 | E6: 1 | F6: 1
A7: s6 | C7: 1 | D7: 1
A8: s7 | C8: 1 | E8: 1
A9: s8 | B9: 1 | E9: 1 | F9: 1
A10: s9 | C10: 1 | D10: 1 | E10: 1 | F10: 1
A11: s10 | D11: 1 | E11: 1 | F11: 1
A12: s11 | B12: 1 | D12: 1
A13: s12 | B13: 1 | C13: 1 | D13: 1
A14: s13 | D14: 1 | E14: 1 | F14: 1
A15: s14 | C15: 1
A16: s15 | B16: 1 | C16: 1 | E16: 1
A17: s16 | D17: 1 | E17: 1
A18: s17 | B18: 1 | D18: 1 | E18: 1
A19: s18 | B19: 1 | C19: 1 | F19: 1
A20: s19 | B20: 1 | D20: 1 | F20: 1
A21: s20 | B21: 1 | C21: 1 | E21: 1 | F21: 1
A22: s21 | C22: 1 | E22: 1
A23: s22 | B23: 1 | C23: 1 | D23: 1 | E23: 1 | F23: 1
A24: s23 | B24: 1 | D24: 1 | E24: 1
A25: s24 | C25: 1 | D25: 1
A26: s25 | B26: 1 | E26: 1
A27: s26 | F27: 1
A28: s27 | B28: 1 | D28: 1 | E28: 1
A29: s28 | C29: 1 | E29: 1 | F29: 1
A30: s29 | C30: 1 | E30: 1
A31: s30 | B31: 1 | D31: 1 | E31: 1 | F31: 1
A32: s31 | B32: 1 | F32: 1
A33: s32 | B33: 1 | E33: 1 | F33: 1
A34: s33 | B34: 1 | C34: 1 | F34: 1
A35: s34 | E35: 1
A36: s35 | B36: 1 | D36: 1 | F36: 1
A37: s36 | E37: 1 | F37: 1
A38: s37 | B38: 1 | E38: 1
A39: s38 | C39: 1 | E39: 1
A40: s39 | B40: 1 | F40: 1
...

Sheet WillingShort
B1: ShortShowers | C1: LessShowers | D1: LessFaucet | E1: LessLaundry | F1: LessDishLoads
A2: s1 | B2: 1 | D2: 1
A3: s3 | C3: 1 | D3: 1
A4: s4 | D4: 1 | F4: 1
A5: s6 | B5: 1 | C5: 1
A6: s7 | D6: 1 | F6: 1
A7: s8 | C7: 1 | D7: 1 | F7: 1
A8: s9 | B8: 1 | C8: 1 | D8: 1
A9: s10 | C9: 1 | D9: 1 | E9: 1 | F9: 1
A10: s11 | C10: 1 | D10: 1
A11: s12 | C11: 1 | D11: 1 | E11: 1
A12: s13 | C12: 1 | D12: 1
A13: s14 | D13: 1 | E13: 1
A14: s15 | C14: 1 | E14: 1 | F14: 1
A15: s16 | B15: 1 | D15: 1 | E15: 1 | F15: 1
A16: s17 | B16: 1
A17: s18 | B17: 1 | D17: 1
A18: s19 | B18: 1
A19: s20 | C19: 1 | F19: 1
A20: s21 | B20: 1 | E20: 1 | F20: 1
A21: s22 | B21: 1 | C21: 1 | D21: 1 | E21: 1 | F21: 1
A22: s23 | E22: 1 | F22: 1
A23: s24 | D23: 1 | E23: 1 | F23: 1
A24: s26 | B24: 1 | C24: 1 | E24: 1
A25: s27 | B25: 1 | C25: 1 | D25: 1 | E25: 1 | F25: 1
A26: s28 | C26: 1 | D26: 1 | E26: 1
A27: s29 | D27: 1 | F27: 1
A28: s30 | B28: 1 | C28: 1 | D28: 1 | E28: 1 | F28: 1
A29: s31 | B29: 1 | D29: 1
A30: s32 | D30: 1 | E30: 1 | F30: 1
A31: s33 | C31: 1 | D31: 1 | E31: 1
A32: s35 | B32: 1
A33: s36 | B33: 1 | C33: 1 | E33: 1
A34: s37 | C34: 1 | F34: 1
A35: s38 | C35: 1 | D35: 1
A36: s39 | C36: 1 | D36: 1 | E36: 1 | F36: 1
A37: s40 | D37: 1 | F37: 1
A38: s41 | C38: 1 | D38: 1 | F38: 1
A39: s42 | B39: 1 | E39: 1 | F39: 1
A40: s43 | B40: 1 | C40: 1 | D40: 1 | F40: 1
...

Sheet MCResults
B1: ObjValue | C1: TotalWater_Current | D1: TotalWater_After | E1: InvestCost
A2: s1 | B2: 8890.6592 | C2: 2111134.2 | D2: 1331424.6 | E2: 50
A3: s2 | B3: 4637.2032 | C3: 786181.59 | D3: 674277.59 | E3: 160
A4: s3 | B4: 6670.5134 | C4: 1505342.5 | D4: 1004595.4
A5: s4 | B5: 5034.8873 | C5: 1033229.1 | D5: 734169.77 | E5: 160
A6: s5 | B6: 8885.1927 | C6: 1369705.8 | D6: 1338131.4
A7: s6 | B7: 5711.8781 | C7: 934541.01 | D7: 860222.61
A8: s7 | B8: 7711.0451 | C8: 1221580.4 | D8: 1161302
A9: s8 | B9: 4011.5905 | C9: 1416335.9 | D9: 587588.93 | E9: 110
A10: s9 | B10: 2822.324 | C10: 582775.97 | D10: 417518.67 | E10: 50
A11: s10 | B11: 3402.084 | C11: 632169 | D11: 497301.8 | E11: 100
A12: s11 | B12: 3808.9936 | C12: 1025556.9 | D12: 551053.25 | E12: 150
A13: s12 | B13: 4729.1133 | C13: 1744243 | D13: 688119.48 | E13: 160
A14: s13 | B14: 4689.2415 | C14: 1793283.4 | D14: 674584.56 | E14: 210
A15: s14 | B15: 5337.972 | C15: 903948.53 | D15: 796381.33 | E15: 50
A16: s15 | B16: 6467.8048 | C16: 980514.99 | D16: 974066.99
A17: s16 | B17: 12250.227 | C17: 2569622 | D17: 1837383.5 | E17: 50
A18: s17 | B18: 6674.4453 | C18: 1823835.6 | D18: 990127.31 | E18: 100
A19: s18 | B19: 8244.2803 | C19: 1560629.1 | D19: 1241608.5
A20: s19 | B20: 8109.6294 | C20: 1338653.6 | D20: 1212293.6 | E20: 60
A21: s20 | B21: 6464.2575 | C21: 1062409.6 | D21: 950942.4 | E21: 150
A22: s21 | B22: 6583.9372 | C22: 1167224.7 | D22: 982520.67 | E22: 60
A23: s22 | B23: 7808.823 | C23: 1413770 | D23: 1153437.2 | E23: 150
A24: s23 | B24: 7063.7071 | C24: 1471851.6 | D24: 1032184.8 | E24: 210
A25: s24 | B25: 8395.496 | C25: 1819822.7 | D25: 1264381.9
A26: s25 | B26: 6943.2796 | C26: 1439804.9 | D26: 1036638.5 | E26: 60
A27: s26 | B27: 7133.2051 | C27: 1237744 | D27: 1059217.6 | E27: 100
A28: s27 | B28: 7750.9493 | C28: 1746558.7 | D28: 1167311.6
A29: s28 | B29: 7888.1612 | C29: 1523632.3 | D29: 1180446 | E29: 50
A30: s29 | B30: 5900.277 | C30: 1418102.5 | D30: 872029.67 | E30: 110
A31: s30 | B31: 8935.4651 | C31: 2079347.9 | D31: 1345702.6
A32: s31 | B32: 7198.809 | C32: 1593333 | D32: 1075121.8 | E32: 60
A33: s32 | B33: 7058.4925 | C33: 1448760.9 | D33: 1047965.7 | E33: 100
A34: s33 | B34: 6127.2274 | C34: 1169414.4 | D34: 891148.7 | E34: 210
A35: s34 | B35: 3603.3848 | C35: 545818.2 | D35: 527618.2 | E35: 100
A36: s35 | B36: 14023.36 | C36: 2162287.8 | D36: 2111951.8
A37: s36 | B37: 8152.0897 | C37: 1680786.9 | D37: 1220194.2 | E37: 50
A38: s37 | B38: 6925.9037 | C38: 1402562.6 | D38: 1011431.3 | E38: 210
A39: s38 | B39: 5615.8952 | C39: 1267358.4 | D39: 829201.09 | E39: 110
A40: s39 | B40: 4923.913 | C40: 1527814 | D40: 681312.19 | E40: 400
...

Sheet MCWaterBefore
B1: Shower | C1: Toilet | D1: Faucets | E1: Laundry | F1: Dishwasher | G1: Outdoor
A2: s1 | B2: 1223040 | C2: 52728 | D2: 104104 | E2: 32240 | F2: 9516 | G2: 689506.17
A3: s2 | B3: 226044 | C3: 123032 | D3: 69784 | E3: 48360 | F3: 19032 | G3: 299929.59
A4: s3 | B4: 856128 | C4: 100048 | D4: 70928 | E4: 16120 | F4: 6344 | G4: 455774.48
A5: s4 | B5: 222768 | C5: 63544 | D5: 57200 | E5: 145080 | F5: 12688 | G5: 531949.1
A6: s5 | B6: 594048 | C6: 135200 | D6: 78936 | E6: 64480 | F6: 25376 | G6: 471665.84
A7: s6 | B7: 137592 | C7: 129792 | D7: 84656 | E7: 32240 | F7: 12688 | G7: 537573.01
A8: s7 | B8: 150696 | C8: 114920 | D8: 132704 | E8: 96720 | F8: 22204 | G8: 704336.38
A9: s8 | B9: 183456 | C9: 59488 | D9: 67496 | E9: 96720 | F9: 25376 | G9: 983799.89
A10: s9 | B10: 84084 | C10: 91936 | D10: 57200 | E10: 112840 | F10: 6344 | G10: 230371.97
A11: s10 | B11: 163800 | C11: 97344 | D11: 48048 | E11: 32240 | F11: 31720 | G11: 259017
A12: s11 | B12: 185640 | C12: 94640 | D12: 76648 | E12: 145080 | F12: 25376 | G12: 498172.93
A13: s12 | B13: 1261260 | C13: 89232 | D13: 73216 | E13: 80600 | F13: 3172 | G13: 236762.98
... A251: s250 | B251: 851760 | C251: 75712 | D251: 70928 | E251: 64480 | F251: 9516 | G251: 795281.16

Sheet MCWaterAfter
B1: Shower | C1: Toilet | D1: Faucets | E1: Laundry | F1: Dishwasher | G1: Outdoor
A2: s1 | B2: 733824 | C2: 52728 | D2: 42588 | E2: 32240 | F2: 9516 | G2: 460528.57
A3: s2 | B3: 161460 | C3: 75712 | D3: 69784 | E3: 48360 | F3: 19032 | G3: 299929.59
A4: s3 | B4: 513676.8 | C4: 100048 | D4: 70928 | E4: 16120 | F4: 6344 | G4: 297478.59
A5: s4 | B5: 114192 | C5: 39104 | D5: 34320 | E5: 145080 | F5: 12688 | G5: 388785.77
A6: s5 | B6: 594048 | C6: 135200 | D6: 47361.6 | E6: 64480 | F6: 25376 | G6: 471665.84
A7: s6 | B7: 102211.2 | C7: 129792 | D7: 50793.6 | E7: 32240 | F7: 7612.8 | G7: 537573.01
A8: s7 | B8: 90417.6 | C8: 114920 | D8: 132704 | E8: 96720 | F8: 22204 | G8: 704336.38
A9: s8 | B9: 47174.4 | C9: 59488 | D9: 27612 | E9: 96720 | F9: 15225.6 | G9: 341368.93
A10: s9 | B10: 84084 | C10: 91936 | D10: 39000 | E10: 67704 | F10: 3806.4 | G10: 130988.27
A11: s10 | B11: 98280 | C11: 59904 | D11: 28828.8 | E11: 32240 | F11: 19032 | G11: 259017
A12: s11 | B12: 111384 | C12: 58240 | D12: 31356 | E12: 145080 | F12: 25376 | G12: 179617.25
A13: s12 | B13: 336679.2 | C13: 54912 | D13: 73216 | E13: 48360 | F13: 3172 | G13: 171780.28
... A251: s250 | B251: 483600 | C251: 75712 | D251: 29016 | E251: 64480 | F251: 5709.6 | G251: 556023.51

Sheet MCActionShort
B1: ShortShowers | C1: LessShowers | D1: LessFaucet | E1: LessLaundry | F1: LessDishLoads
A2: s1 | C2: 11.2 | D2: 36.4
A3: s3 | B3: 11.2
A4: s4 | B4: 4.8 | D4: 20
A5: s5 | D5: 27.6
A6: s6 | B6: 3.6 | D6: 29.6 | F6: 1.6
A7: s7 | C7: 2.4
A8: s8 | B8: 4.8 | C8: 5.6 | D8: 23.6 | F8: 3.2
A9: s9 | E9: 2.8 | F9: 0.8
A10: s10 | B10: 2 | D10: 16.8 | F10: 4
A11: s11 | B11: 2 | D11: 26.8
A12: s12 | B12: 13.2 | C12: 13.2 | E12: 2
A13: s13 | B13: 9.2 | C13: 9.2 | D13: 31.6 | E13: 0.4
A14: s14 | C14: 6 | D14: 26 | E14: 0.8 | F14: 3.6
A15: s15 | E15: 0.4
A16: s16 | D16: 32 | E16: 3.2
A17: s17 | B17: 10.4 | C17: 10.4 | D17: 43.2
A18: s18 | B18: 3.6 | E18: 0.8 | F18: 4
A19: s20 | C19: 2.4
A20: s21 | B20: 2 | C20: 11.2 | D20: 34 | E20: 2
A21: s22 | B21: 4 | C21: 4 | F21: 0.4
A22: s23 | E22: 2.8 | F22: 1.2
A23: s24 | B23: 12 | D23: 22.8 | F23: 1.6
A24: s25 | C24: 6.4 | F24: 1.2
A25: s26 | C25: 13.2 | E25: 3.2 | F25: 2.8
A26: s27 | C26: 6.8 | D26: 28.4 | E26: 1.6
A27: s28 | B27: 7.6 | D27: 22 | E27: 0.8 | F27: 2.8
A28: s29 | B28: 9.6 | C28: 9.6 | F28: 0.8
A29: s30 | C29: 8 | D29: 42.8
A30: s31 | B30: 9.6 | C30: 9.6 | D30: 22 | E30: 1.6
A31: s32 | B31: 8 | C31: 8 | E31: 0.8 | F31: 3.6
A32: s35 | D32: 44
A33: s36 | C33: 6
A34: s37 | E34: 0.8
A35: s38 | B35: 4 | D35: 38.4 | F35: 1.6
A36: s39 | C36: 2.8 | D36: 43.2
A37: s40 | D37: 21.2 | F37: 3.2
A38: s41 | B38: 4.4 | D38: 45.6 | E38: 2.4 | F38: 0.4
A39: s42 | B39: 4.4
A40: s43 | B40: 10.8 | F40: 2.4
...

Sheet MCActionLong
B1: LowFlowShower | C1: LowFLowToilet | D1: AeratorFaucet | E1: HELaundry
A2: s1 | D2: 1
A3: s2 | B3: 1 | C3: 1
A4: s4 | B4: 1 | C4: 1
A5: s8 | B5: 1 | D5: 1
A6: s9 | D6: 1
A7: s10 | C7: 1
A8: s11 | C8: 1 | D8: 1
A9: s12 | B9: 1 | C9: 1
A10: s13 | B10: 1 | C10: 1 | D10: 1
A11: s14 | D11: 1
A12: s16 | D12: 1
A13: s17 | C13: 1
A14: s19 | B14: 1
A15: s20 | C15: 1 | D15: 1
A16: s21 | B16: 1
A17: s22 | C17: 1 | D17: 1
A18: s23 | B18: 1 | C18: 1 | D18: 1
A19: s25 | B19: 1
A20: s26 | C20: 1
A21: s28 | D21: 1
A22: s29 | B22: 1 | D22: 1
A23: s31 | B23: 1
A24: s32 | C24: 1
A25: s33 | B25: 1 | C25: 1 | D25: 1
A26: s34 | C26: 1
A27: s36 | D27: 1
A28: s37 | B28: 1 | C28: 1 | D28: 1
A29: s38 | B29: 1 | D29: 1
A30: s39 | E30: 1
A31: s40 | C31: 1
A32: s41 | B32: 1 | C32: 1 | D32: 1
A33: s42 | B33: 1 | D33: 1
A34: s43 | D34: 1
A35: s44 | B35: 1 | C35: 1 | D35: 1
A36: s45 | B36: 1 | C36: 1 | D36: 1
A37: s46 | D37: 1
A38: s47 | B38: 1 | D38: 1
A39: s49 | C39: 1 | D39: 1
A40: s50 | B40: 1 | D40: 1
...

Sheet MCWillingShort
B1: ShortShowers | C1: LessShowers | D1: LessFaucet | E1: LessLaundry | F1: LessDishLoads
A2: s1 | B2: Eps | C2: 1 | D2: 1 | E2: Eps | F2: Eps
A3: s2 | B3: Eps | C3: Eps | D3: Eps | E3: Eps | F3: Eps
A4: s3 | B4: 1 | C4: Eps | D4: Eps | E4: Eps | F4: Eps
A5: s4 | B5: 1 | C5: Eps | D5: 1 | E5: Eps | F5: Eps
A6: s5 | B6: Eps | C6: Eps | D6: 1 | E6: Eps | F6: Eps
A7: s6 | B7: 1 | C7: Eps | D7: 1 | E7: Eps | F7: 1
A8: s7 | B8: Eps | C8: 1 | D8: Eps | E8: Eps | F8: Eps
A9: s8 | B9: 1 | C9: 1 | D9: 1 | E9: Eps | F9: 1
A10: s9 | B10: Eps | C10: Eps | D10: Eps | E10: 1 | F10: 1
A11: s10 | B11: 1 | C11: Eps | D11: 1 | E11: Eps | F11: 1
A12: s11 | B12: 1 | C12: Eps | D12: 1 | E12: Eps | F12: Eps
A13: s12 | B13: 1 | C13: 1 | D13: Eps | E13: 1 | F13: Eps
A14: s13 | B14: 1 | C14: 1 | D14: 1 | E14: 1 | F14: Eps
A15: s14 | B15: Eps | C15: 1 | D15: 1 | E15: 1 | F15: 1
A16: s15 | B16: Eps | C16: Eps | D16: Eps | E16: 1 | F16: Eps
A17: s16 | B17: Eps | C17: Eps | D17: 1 | E17: 1 | F17: Eps
A18: s17 | B18: 1 | C18: 1 | D18: 1 | E18: Eps | F18: Eps
A19: s18 | B19: 1 | C19: Eps | D19: Eps | E19: 1 | F19: 1
A20: s19 | B20: Eps | C20: Eps | D20: Eps | E20: Eps | F20: Eps
A21: s20 | B21: Eps | C21: 1 | D21: Eps | E21: Eps | F21: Eps
A22: s21 | B22: 1 | C22: 1 | D22: 1 | E22: 1 | F22: Eps
A23: s22 | B23: 1 | C23: 1 | D23: Eps | E23: Eps | F23: 1
A24: s23 | B24: Eps | C24: Eps | D24: Eps | E24: 1 | F24: 1
A25: s24 | B25: 1 | C25: Eps | D25: 1 | E25: Eps | F25: 1
A26: s25 | B26: Eps | C26: 1 | D26: Eps | E26: Eps | F26: 1
A27: s26 | B27: Eps | C27: 1 | D27: Eps | E27: 1 | F27: 1
A28: s27 | B28: Eps | C28: 1 | D28: 1 | E28: 1 | F28: Eps
A29: s28 | B29: 1 | C29: Eps | D29: 1 | E29: 1 | F29: 1
A30: s29 | B30: 1 | C30: 1 | D30: Eps | E30: Eps | F30: 1
A31: s30 | B31: Eps | C31: 1 | D31: 1 | E31: Eps | F31: Eps
A32: s31 | B32: 1 | C32: 1 | D32: 1 | E32: 1 | F32: Eps
A33: s32 | B33: 1 | C33: 1 | D33: Eps | E33: 1 | F33: 1
A34: s33 | B34: Eps | C34: Eps | D34: Eps | E34: Eps | F34: Eps
A35: s34 | B35: Eps | C35: Eps | D35: Eps | E35: Eps | F35: Eps
A36: s35 | B36: Eps | C36: Eps | D36: 1 | E36: Eps | F36: Eps
A37: s36 | B37: Eps | C37: 1 | D37: Eps | E37: Eps | F37: Eps
A38: s37 | B38: Eps | C38: Eps | D38: Eps | E38: 1 | F38: Eps
A39: s38 | B39: 1 | C39: Eps | D39: 1 | E39: Eps | F39: 1
A40: s39 | B40: Eps | C40: 1 | D40: 1 | E40: Eps | F40: Eps
...

Sheet MCWillingLong
B1: LowFlowShower | C1: LowFLowToilet | D1: AeratorFaucet | E1: HELaundry | F1: HEDishwasher
A2: s1 | B2: Eps | C2: Eps | D2: 1 | E2: Eps | F2: 1
A3: s2 | B3: 1 | C3: 1 | D3: Eps | E3: 1 | F3: 1
A4: s3 | B4: Eps | C4: Eps | D4: Eps | E4: 1 | F4: 1
A5: s4 | B5: 1 | C5: 1 | D5: Eps | E5: Eps | F5: 1
A6: s5 | B6: Eps | C6: Eps | D6: Eps | E6: Eps | F6: Eps
A7: s6 | B7: Eps | C7: Eps | D7: Eps | E7: 1 | F7: 1
A8: s7 | B8: Eps | C8: Eps | D8: Eps | E8: Eps | F8: Eps
A9: s8 | B9: 1 | C9: Eps | D9: 1 | E9: Eps | F9: 1
A10: s9 | B10: Eps | C10: Eps | D10: 1 | E10: 1 | F10: 1
A11: s10 | B11: Eps | C11: 1 | D11: Eps | E11: Eps | F11: Eps
A12: s11 | B12: Eps | C12: 1 | D12: 1 | E12: Eps | F12: 1
A13: s12 | B13: 1 | C13: 1 | D13: Eps | E13: Eps | F13: 1
A14: s13 | B14: 1 | C14: 1 | D14: 1 | E14: 1 | F14: 1
A15: s14 | B15: Eps | C15: Eps | D15: 1 | E15: 1 | F15: 1
A16: s15 | B16: Eps | C16: Eps | D16: Eps | E16: 1 | F16: 1
A17: s16 | B17: Eps | C17: Eps | D17: 1 | E17: Eps | F17: 1
A18: s17 | B18: Eps | C18: 1 | D18: Eps | E18: Eps | F18: 1
A19: s18 | B19: Eps | C19: Eps | D19: Eps | E19: Eps | F19: 1
A20: s19 | B20: 1 | C20: Eps | D20: Eps | E20: 1 | F20: Eps
A21: s20 | B21: Eps | C21: 1 | D21: 1 | E21: Eps | F21: Eps
A22: s21 | B22: 1 | C22: Eps | D22: Eps | E22: 1 | F22: Eps
A23: s22 | B23: Eps | C23: 1 | D23: 1 | E23: 1 | F23: Eps
A24: s23 | B24: 1 | C24: 1 | D24: 1 | E24: Eps | F24: 1
A25: s24 | B25: Eps | C25: Eps | D25: Eps | E25: 1 | F25: Eps
A26: s25 | B26: 1 | C26: Eps | D26: Eps | E26: 1 | F26: 1
A27: s26 | B27: Eps | C27: 1 | D27: Eps | E27: Eps | F27: Eps
A28: s27 | B28: Eps | C28: Eps | D28: Eps | E28: Eps | F28: 1
A29: s28 | B29: Eps | C29: Eps | D29: 1 | E29: Eps | F29: Eps
A30: s29 | B30: 1 | C30: Eps | D30: 1 | E30: Eps | F30: 1
A31: s30 | B31: Eps | C31: Eps | D31: Eps | E31: 1 | F31: 1
A32: s31 | B32: 1 | C32: Eps | D32: Eps | E32: Eps | F32: Eps
A33: s32 | B33: Eps | C33: 1 | D33: Eps | E33: Eps | F33: 1
A34: s33 | B34: 1 | C34: 1 | D34: 1 | E34: Eps | F34: 1
A35: s34 | B35: Eps | C35: 1 | D35: Eps | E35: Eps | F35: Eps
A36: s35 | B36: Eps | C36: Eps | D36: Eps | E36: 1 | F36: 1
A37: s36 | B37: Eps | C37: Eps | D37: 1 | E37: Eps | F37: Eps
A38: s37 | B38: 1 | C38: 1 | D38: 1 | E38: 1 | F38: 1
A39: s38 | B39: 1 | C39: Eps | D39: 1 | E39: 1 | F39: 1
A40: s39 | B40: Eps | C40: Eps | D40: Eps | E40: 1 | F40: 1
...

Sheet MCOutdoorBase
A1: s1 | B1: s2 | C1: s3 | D1: s4 | E1: s5 | F1: s6 | G1: s7 | H1: s8 | I1: s9 | J1: s10 | K1: s11 | L1: s12 | M1: s13 | N1: s14 | O1: s15 | P1: s16 | Q1: s17 | R1: s18 | S1: s19 | T1: s20 | U1: s21 | V1: s22 | W1: s23 | X1: s24 | Y1: s25 | Z1: s26 | AA1: s27 | AB1: s28 | AC1: s29 | AD1: s30 | AE1: s31 | AF1: s32 | AG1: s33 | AH1: s34 | AI1: s35 | AJ1: s36 | AK1: s37 | AL1: s38 | AM1: s39 | AN1: s40 | AO1: s41 | AP1: s42 | AQ1: s43 | AR1: s44 | AS1: s45 | AT1: s46 | AU1: s47 | AV1: s48 | AW1: s49 | AX1: s50 | AY1: s51 | AZ1: s52 | BA1: s53 | BB1: s54 | BC1: s55 | BD1: s56 | BE1: s57 | BF1: s58 | BG1: s59 | BH1: s60 | BI1: s61 | BJ1: s62 | BK1: s63 | BL1: s64 | BM1: s65 | BN1: s66 | BO1: s67 | BP1: s68 | BQ1: s69 | BR1: s70 | BS1: s71 | BT1: s72 | BU1: s73 | BV1: s74 | BW1: s75 | BX1: s76 | BY1: s77 | BZ1: s78 | CA1: s79 | CB1: s80 | CC1: s81 | CD1: s82 | CE1: s83 | CF1: s84 | CG1: s85 | CH1: s86 | CI1: s87 | CJ1: s88 | CK1: s89 | CL1: s90 | CM1: s91 | CN1: s92 | CO1: s93 | CP1: s94 | CQ1: s95 | CR1: s96 | CS1: s97 | CT1: s98 | CU1: s99 | CV1: s100 | CW1: s101 | CX1: s102 | CY1: s103 | CZ1: s104 | DA1: s105 | DB1: s106 | DC1: s107 | DD1: s108 | DE1: s109 | DF1: s110 | DG1: s111 | DH1: s112 | DI1: s113 | DJ1: s114 | DK1: s115 | DL1: s116 | DM1: s117 | DN1: s118 | DO1: s119 | DP1: s120 | DQ1: s121 | DR1: s122 | DS1: s123 | DT1: s124 | DU1: s125 | DV1: s126 | DW1: s127 | DX1: s128 | DY1: s129 | DZ1: s130 | EA1: s131 | EB1: s132 | EC1: s133 | ED1: s134 | EE1: s135 | EF1: s136 | EG1: s137 | EH1: s138 | EI1: s139 | EJ1: s140 | EK1: s141 | EL1: s142 | EM1: s143 | EN1: s144 | EO1: s145 | EP1: s146 | EQ1: s147 | ER1: s148 | ES1: s149 | ET1: s150 | EU1: s151 | EV1: s152 | EW1: s153 | EX1: s154 | EY1: s155 | EZ1: s156 | FA1: s157 | FB1: s158 | FC1: s159 | FD1: s160 | FE1: s161 | FF1: s162 | FG1: s163 | FH1: s164 | FI1: s165 | FJ1: s166 | FK1: s167 | FL1: s168 | FM1: s169 | FN1: s170 | FO1: s171 | FP1: s172 | FQ1: s173 | FR1: s174 | FS1: s175 | FT1: s176 | FU1: s177 | FV1: s178 | FW1: s179 | FX1: s180 | FY1: s181 | FZ1: s182 | GA1: s183 | GB1: s184 | GC1: s185 | GD1: s186 | GE1: s187 | GF1: s188 | GG1: s189 | GH1: s190 | GI1: s191 | GJ1: s192 | GK1: s193 | GL1: s194 | GM1: s195 | GN1: s196 | GO1: s197 | GP1: s198 | GQ1: s199 | GR1: s200 | GS1: s201 | GT1: s202 | GU1: s203 | GV1: s204 | GW1: s205 | GX1: s206 | GY1: s207 | GZ1: s208 | HA1: s209 | HB1: s210 | HC1: s211 | HD1: s212 | HE1: s213 | HF1: s214 | HG1: s215 | HH1: s216 | HI1: s217 | HJ1: s218 | HK1: s219 | HL1: s220 | HM1: s221 | HN1: s222 | HO1: s223 | HP1: s224 | HQ1: s225 | HR1: s226 | HS1: s227 | HT1: s228 | HU1: s229 | HV1: s230 | HW1: s231 | HX1: s232 | HY1: s233 | HZ1: s234 | IA1: s235 | IB1: s236 | IC1: s237 | ID1: s238 | IE1: s239 | IF1: s240 | IG1: s241 | IH1: s242 | II1: s243 | IJ1: s244 | IK1: s245 | IL1: s246 | IM1: s247 | IN1: s248 | IO1: s249 | IP1: s250
A2: 1325.9734 | B2: 576.78767 | C2: 876.48938 | D2: 1022.979 | E2: 907.04969 | F2: 1033.7943 | G2: 1354.493 | H2: 1891.9229 | I2: 443.02302 | J2: 498.10962 | K2: 958.02487 | L2: 455.31343 | M2: 1521.4219 | N2: 1130.8626 | O2: 561.30575 | P2: 1840.2807 | Q2: 1321.9761 | R2: 1946.1098 | S2: 1267.7338 | T2: 1315.2954 | U2: 1315.4628 | V2: 1353.8885 | W2: 1918.3839 | X2: 952.05896 | Y2: 1004.3556 | Z2: 1285.477 | AA2: 1575.0666 | AB2: 934.16212 | AC2: 1048.9201 | AD2: 1978.346 | AE2: 1358.102 | AF2: 1107.1787 | AG2: 572.97389 | AH2: 474.25038 | AI2: 1211.8457 | AJ2: 1572.1826 | AK2: 447.83572 | AL2: 1236.8278 | AM2: 1841.3038 | AN2: 1902.1139 | AO2: 1785.0366 | AP2: 1180.4045 | AQ2: 1149.76 | AR2: 1727.0148 | AS2: 1586.3679 | AT2: 1037.2243 | AU2: 1525.0477 | AV2: 1821.7744 | AW2: 1921.8327 | AX2: 1894.643 | AY2: 1664.2621 | AZ2: 423.61849 | BA2: 1089.7973 | BB2: 740.59255 | BC2: 630.62505 | BD2: 548.63787 | BE2: 1798.4232 | BF2: 490.12483 | BG2: 618.92789 | BH2: 1945.9851 | BI2: 1236.6972 | BJ2: 613.57552 | BK2: 1655.2329 | BL2: 427.52204 | BM2: 459.5432 | BN2: 1847.1468 | BO2: 1531.8738 | BP2: 932.10597 | BQ2: 1630.8409 | BR2: 1788.352 | BS2: 1277.6721 | BT2: 1719.0846 | BU2: 675.09693 | BV2: 1675.6236 | BW2: 1544.5571 | BX2: 453.51919 | BY2: 516.89262 | BZ2: 858.77632 | CA2: 1891.6006 | CB2: 1325.8283 | CC2: 1300.0222 | CD2: 1428.504 | CE2: 1547.9947 | CF2: 1355.3732 | CG2: 589.73622 | CH2: 873.75523 | CI2: 793.75342 | CJ2: 1125.4145 | CK2: 1495.6627 | CL2: 1147.2301 | CM2: 1013.5931 | CN2: 491.52034 | CO2: 1154.3361 | CP2: 1819.0234 | CQ2: 791.27737 | CR2: 400.37176 | CS2: 1048.6028 | CT2: 1258.7585 | CU2: 864.57175 | CV2: 1990.9056 | CW2: 648.39708 | CX2: 1229.1972 | CY2: 1026.3431 | CZ2: 1327.2888 | DA2: 774.4261 | DB2: 744.50787 | DC2: 1755.0303 | DD2: 1185.4589 | DE2: 541.48602 | DF2: 481.00861 | DG2: 1012.8943 | DH2: 1624.9174 | DI2: 1342.0449 | DJ2: 1373.4205 | DK2: 1273.6781 | DL2: 566.65784 | DM2: 1964.0126 | DN2: 1118.7606 | DO2: 1217.422 | DP2: 521.56137 | DQ2: 847.97815 | DR2: 539.53842 | DS2: 933.13958 | DT2: 975.19974 | DU2: 1764.6992 | DV2: 1014.3075 | DW2: 1748.6484 | DX2: 556.86559 | DY2: 1225.239 | DZ2: 546.76818 | EA2: 1485.0847 | EB2: 585.996 | EC2: 1040.3849 | ED2: 1401.0512 | EE2: 754.37661 | EF2: 712.98453 | EG2: 1765.7994 | EH2: 748.37049 | EI2: 1425.4359 | EJ2: 1729.9794 | EK2: 1551.5982 | EL2: 1879.175 | EM2: 1551.4954 | EN2: 1939.332 | EO2: 543.84508 | EP2: 1688.8755 | EQ2: 1075.7808 | ER2: 765.4103 | ES2: 859.19746 | ET2: 1717.3166 | EU2: 1615.2214 | EV2: 983.86331 | EW2: 850.68298 | EX2: 960.73038 | EY2: 1738.2975 | EZ2: 1368.5292 | FA2: 1238.4903 | FB2: 646.35069 | FC2: 1670.3669 | FD2: 1163.4709 | FE2: 840.94614 | FF2: 891.7555 | FG2: 1221.1706 | FH2: 419.51323 | FI2: 1747.2664 | FJ2: 1583.7069 | FK2: 1646.7421 | FL2: 1015.984 | FM2: 1549.8035 | FN2: 959.76957 | FO2: 1986.8227 | FP2: 1392.4972 | FQ2: 817.61544 | FR2: 1721.4288 | FS2: 1584.6017 | FT2: 881.23759 | FU2: 1297.2967 | FV2: 424.07677 | FW2: 1459.6986 | FX2: 1206.9731 | FY2: 1915.8385 | FZ2: 1070.7895 | GA2: 1131.3703 | GB2: 1045.8752 | GC2: 1284.6097 | GD2: 627.29556 | GE2: 828.20714 | GF2: 1006.8629 | GG2: 498.06228 | GH2: 1255.6752 | GI2: 1353.2068 | GJ2: 603.15236 | GK2: 1649.9275 | GL2: 1655.9013 | GM2: 1023.1495 | GN2: 431.17465 | GO2: 763.92061 | GP2: 1653.9811 | GQ2: 1851.0598 | GR2: 1283.4205 | GS2: 1245.6271 | GT2: 1780.9786 | GU2: 950.90337 | GV2: 1992.5684 | GW2: 1307.2523 | GX2: 1135.9798 | GY2: 1293.9877 | GZ2: 899.44099 | HA2: 1640.2261 | HB2: 472.65742 | HC2: 766.36247 | HD2: 485.53072 | HE2: 960.26465 | HF2: 1676.8374 | HG2: 1816.2176 | HH2: 1630.2395 | HI2: 1291.8266 | HJ2: 797.42 | HK2: 1717.3022 | HL2: 699.44229 | HM2: 1404.908 | HN2: 1041.6434 | HO2: 1211.5927 | HP2: 1825.7163 | HQ2: 972.46782 | HR2: 1711.12 | HS2: 1432.3106 | HT2: 1068.9955 | HU2: 665.91051 | HV2: 776.26959 | HW2: 1519.7316 | HX2: 1531.9303 | HY2: 1595.2741 | HZ2: 1511.1214 | IA2: 585.76919 | IB2: 1359.4561 | IC2: 1887.5847 | ID2: 971.50457 | IE2: 1732.2895 | IF2: 860.00127 | IG2: 1519.9017 | IH2: 623.93563 | II2: 1341.2619 | IJ2: 1950.2768 | IK2: 1196.7586 | IL2: 530.68452 | IM2: 1317.1501 | IN2: 1543.8524 | IO2: 1800.5437 | IP2: 1529.3868

Sheet MCOutdoorTarget
